Workbook

Sheet Feuil1
B1: Level Item | C1: Valeur d'obtention minimum | D1: % focus N | F1: Nom de la stat | G1: Nom de rune | H1: Poids Rune | I1: Stat par rune | J1: Prix Rune | K1: Prix / poids runes | L1: Nombre de stats
B2: 79 | C2: 11000 | D2: 14 | F2: % Dommages aux sorts | G2: Do Per So | H2: 15 | I2: 1 | J2: 27934 | K2: =J2/H2 -> 1862.2667
F3: % Dommages d'armes | G3: Do Per Ar | H3: 15 | I3: 1 | J3: 6321 | K3: =J3/H3 -> 421.4
F4: % Dommages distance | G4: Do Per Di | H4: 15 | I4: 1 | J4: 29031 | K4: =J4/H4 -> 1935.4
A5: Par Rune, Sometimes | F5: % Dommages mêlée | G5: Do Per Mé | H5: 15 | I5: 1 | J5: 9398 | K5: =J5/H5 -> 626.53333
A6: Par Item | F6: % Résistance Air | G6: Ré Per Air | H6: 6 | I6: 1 | J6: 1264 | K6: =J6/H6 -> 210.66667
A7: Apres brisage | F7: % Résistance Distance | G7: Ré Per Di | H7: 10 | I7: 1 | J7: 1898 | K7: =J7/H7 -> 189.8
F8: % Résistance Eau | G8: Ré Per Eau | H8: 6 | I8: 1 | J8: 1514 | K8: =J8/H8 -> 252.33333
F9: % Résistance Feu | G9: Ré Per Feu | H9: 6 | I9: 1 | J9: 1051 | K9: =J9/H9 -> 175.16667
F10: % Résistance Mêlée | G10: Ré Per Mé | H10: 10 | I10: 1 | J10: 3961 | K10: =J10/H10 -> 396.1
F11: % Résistance Neutre | G11: Ré Per Neutre | H11: 6 | I11: 1 | J11: 1209 | K11: =J11/H11 -> 201.5
F12: % Résistance Terre | G12: Ré Per Terre | H12: 6 | I12: 1 | J12: 1438 | K12: =J12/H12 -> 239.66667
F13: Agilité | G13: Age | H13: 1 | I13: 1 | J13: 99 | K13: =J13/H13 -> 99
F14: Chance | G14: Cha | H14: 1 | I14: 1 | J14: 75 | K14: =J14/H14 -> 75 | L14: 30
F15: Critique | G15: Cri | H15: 10 | I15: 1 | J15: 2335 | K15: =J15/H15 -> 233.5
F16: Dommage | G16: Do | H16: 20 | I16: 1 | J16: 883 | K16: =J16/H16 -> 44.15 | L16: 4.5
F17: Dommage Air | G17: Do Air | H17: 5 | I17: 1 | J17: 1237 | K17: =J17/H17 -> 247.4
F18: Dommage Critique | G18: Do Cri | H18: 5 | I18: 1 | J18: 1562 | K18: =J18/H18 -> 312.4
F19: Dommage Eau | G19: Do Eau | H19: 5 | I19: 1 | J19: 1208 | K19: =J19/H19 -> 241.6
F20: Dommage Feu | G20: Do Feu | H20: 5 | I20: 1 | J20: 951 | K20: =J20/H20 -> 190.2
F21: Dommage Neutre | G21: Do Neutre | H21: 5 | I21: 1 | J21: 1143 | K21: =J21/H21 -> 228.6
F22: Dommage Pièges | G22: Do Pi | H22: 5 | I22: 1 | J22: 315 | K22: =J22/H22 -> 63
F23: Dommage Poussée | G23: Do Pi | H23: 5 | I23: 1 | J23: 244 | K23: =J23/H23 -> 48.8
F24: Dommage Terre | G24: Do Terre | H24: 5 | I24: 1 | J24: 1188 | K24: =J24/H24 -> 237.6
F25: Dommages Renvoyés | G25: Do Ren | H25: 5 | I25: 1 | J25: 736 | K25: =J25/H25 -> 147.2
F26: Esquive Pa | G26: Ré Pa | H26: 7 | I26: 1 | J26: 580 | K26: =J26/H26 -> 82.857143
F27: Esquive Pm | G27: Ré Pme | H27: 7 | I27: 1 | J27: 330 | K27: =J27/H27 -> 47.142857
F28: Force | G28: Fo | H28: 1 | I28: 1 | J28: 70 | K28: =J28/H28 -> 70
... F30: Initiative | G30: Ini | H30: 1 | I30: 10 | J30: 75 | K30: =J30/H30 -> 75
F31: Intelligence | G31: Ine | H31: 1 | I31: 1 | J31: 57 | K31: =J31/H31 -> 57 | L31: 30
F32: Invocation | G32: Invo | H32: 30 | I32: 1 | J32: 5297 | K32: =J32/H32 -> 176.56667
F33: PA | G33: Ga Pa | H33: 100 | I33: 1 | J33: 24815 | K33: =J33/H33 -> 248.15 | L33: 1
F34: PM | G34: Ga Pme | H34: 90 | I34: 1 | J34: 22929 | K34: =J34/H34 -> 254.76667
F35: PO | G35: Po | H35: 51 | I35: 1 | J35: 9260 | K35: =J35/H35 -> 181.56863
F36: Pods | G36: Pod | H36: 2.5 | I36: 10 | J36: 152 | K36: =J36/H36 -> 60.8
F37: Prospection | G37: Prospe | H37: 3 | I37: 1 | J37: 413 | K37: =J37/H37 -> 137.66667
F38: Puissance | G38: Pui | H38: 2 | I38: 1 | J38: 241 | K38: =J38/H38 -> 120.5
F39: Puissances Pièges | G39: Per Pi | H39: 2 | I39: 1 | J39: 97 | K39: =J39/H39 -> 48.5
F40: Résistance Air | G40: Ré Air | H40: 2 | I40: 1 | J40: 328 | K40: =J40/H40 -> 164
F41: Résistance Critiques | G41: Ré Cri | H41: 2 | I41: 1 | J41: 334 | K41: =J41/H41 -> 167
...

Sheet Coeff
A1: Custom | B1: Actuel | C1: n+1 | D1: n+2 | E1: n+3 | F1: n+10 | G1: n+100 | H1: n+1000 | I1: 100
A2: 100 | B2: =Feuil1!D2 -> 14 | C2: =-(2.63*POWER(10,-5)-5.958*POWER(10,-10)*B2)*POWER(B2,2)+B2 -> 13.994847 | D2: =-(2.63*POWER(10,-5)-5.958*POWER(10,-10)*C2)*POWER(C2,2)+C2 -> 13.989697 | E2: =-(2.63*POWER(10,-5)-5.958*POWER(10,-10)*D2)*POWER(D2,2)+D2 -> 13.984552 | F2: {=_xlfn.REDUCE($B$2,_xlfn.SEQUENCE(10),_xlfn.LAMBDA(_xlpm.x,_xlpm.i,-(0.0000263-0.0000000005958*_xlpm.x)*_xlpm.x^2+_xlpm.x))} -> 13.948639 | G2: {=_xlfn.REDUCE($B$2,_xlfn.SEQUENCE(100),_xlfn.LAMBDA(_xlpm.x,_xlpm.i,-(0.0000263-0.0000000005958*_xlpm.x)*_xlpm.x^2+_xlpm.x))} -> 13.502802 | H2: {=_xlfn.REDUCE($B$2,_xlfn.SEQUENCE(1000),_xlfn.LAMBDA(_xlpm.x,_xlpm.i,-(0.0000263-0.0000000005958*_xlpm.x)*_xlpm.x^2+_xlpm.x))} -> 10.232303 | I2: {=_xlfn.REDUCE($B$2,_xlfn.SEQUENCE(I1),_xlfn.LAMBDA(_xlpm.x,_xlpm.i,-(0.0000263-0.0000000005958*_xlpm.x)*_xlpm.x^2+_xlpm.x))} -> 13.502802

Sheet Qte
A1: Nom de la stat | B1: Nom de rune | C1: Poids Rune | D1: Stat par rune | E1: Prix Rune | F1: Prix / poids runes | G1: Nombre de stats | H1: Poids ligne | I1: Poids focus | J1: ="Nombre de rune obtenu a " & TEXT(Coeff!A2,"0,00") & "%" -> Nombre de rune obtenu a 100,00% | K1: ="Nombre de rune obtenu a " & TEXT(Coeff!B2,"0,00") & "%" -> Nombre de rune obtenu a 14,00% | L1: ="Nombre de rune obtenu a " & TEXT(Coeff!C2,"0,00") & "%" -> Nombre de rune obtenu a 13,99% | M1: ="Nombre de rune obtenu a " & TEXT(Coeff!D2,"0,00") & "%" -> Nombre de rune obtenu a 13,99% | N1: ="Nombre de rune obtenu a " & TEXT(Coeff!E2,"0,00") & "%" -> Nombre de rune obtenu a 13,98% | O1: ="Nombre de rune obtenu a " & TEXT(Coeff!F2,"0,00") & "%" -> Nombre de rune obtenu a 13,95% | P1: ="Nombre de rune obtenu a " & TEXT(Coeff!G2,"0,00") & "%" -> Nombre de rune obtenu a 13,50% | Q1: ="Nombre de rune obtenu a " & TEXT(Coeff!H2,"0,00") & "%" -> Nombre de rune obtenu a 10,23% | R1: ="Nombre de rune obtenu a " & TEXT(Coeff!I2,"0,00") & "%" -> Nombre de rune obtenu a 13,50%
A2: % Dommages aux sorts | B2: Do Per So | C2: 15 | D2: 1 | E2: =Feuil1!J2 -> 27934 | F2: =E2/C2 -> 1862.2667 | G2: =Feuil1!L2 -> 0 | H2: =IF(OR(G2="",G2=0,C2="",C2=0,D2="",D2=0),"",3*G2*C2/D2*Feuil1!$B$2/200+1) | I2: =IF(H2="","",IF(H2=0,"",H2+(SUM($H$2:$H$1004))/2-H2/2)) | J2: =IF(H2="","",IF(H2=0,0,$I2/$C2*Coeff!A$2/100)) | K2: =IF(I2="","",IF(I2=0,0,$I2/$C2*Coeff!B$2/100)) | L2: =IF(J2="","",IF(J2=0,0,$I2/$C2*Coeff!C$2/100)) | M2: =IF(K2="","",IF(K2=0,0,$I2/$C2*Coeff!D$2/100)) | N2: =IF(L2="","",IF(L2=0,0,$I2/$C2*Coeff!E$2/100)) | O2: =IF(M2="","",IF(M2=0,0,$I2/$C2*Coeff!F$2/100)) | P2: =IF(N2="","",IF(N2=0,0,$I2/$C2*Coeff!G$2/100)) | Q2: =IF(O2="","",IF(O2=0,0,$I2/$C2*Coeff!H$2/100)) | R2: =IF(P2="","",IF(P2=0,0,$I2/$C2*Coeff!I$2/100))
A3: % Dommages d'armes | B3: Do Per Ar | C3: 15 | D3: 1 | E3: =Feuil1!J3 -> 6321 | F3: =E3/C3 -> 421.4 | G3: =Feuil1!L3 -> 0 | H3: =IF(OR(G3="",G3=0,C3="",C3=0,D3="",D3=0),"",3*G3*C3/D3*Feuil1!$B$2/200+1) | I3: =IF(H3="","",IF(H3=0,"",H3+(SUM($H$2:$H$1004))/2-H3/2)) | J3: =IF(H3="","",IF(H3=0,0,$I3/$C3*Coeff!A$2/100)) | K3: =IF(I3="","",IF(I3=0,0,$I3/$C3*Coeff!B$2/100)) | L3: =IF(J3="","",IF(J3=0,0,$I3/$C3*Coeff!C$2/100)) | M3: =IF(K3="","",IF(K3=0,0,$I3/$C3*Coeff!D$2/100)) | N3: =IF(L3="","",IF(L3=0,0,$I3/$C3*Coeff!E$2/100)) | O3: =IF(M3="","",IF(M3=0,0,$I3/$C3*Coeff!F$2/100)) | P3: =IF(N3="","",IF(N3=0,0,$I3/$C3*Coeff!G$2/100)) | Q3: =IF(O3="","",IF(O3=0,0,$I3/$C3*Coeff!H$2/100)) | R3: =IF(P3="","",IF(P3=0,0,$I3/$C3*Coeff!I$2/100))
A4: % Dommages distance | B4: Do Per Di | C4: 15 | D4: 1 | E4: =Feuil1!J4 -> 29031 | F4: =E4/C4 -> 1935.4 | G4: =Feuil1!L4 -> 0 | H4: =IF(OR(G4="",G4=0,C4="",C4=0,D4="",D4=0),"",3*G4*C4/D4*Feuil1!$B$2/200+1) | I4: =IF(H4="","",IF(H4=0,"",H4+(SUM($H$2:$H$1004))/2-H4/2)) | J4: =IF(H4="","",IF(H4=0,0,$I4/$C4*Coeff!A$2/100)) | K4: =IF(I4="","",IF(I4=0,0,$I4/$C4*Coeff!B$2/100)) | L4: =IF(J4="","",IF(J4=0,0,$I4/$C4*Coeff!C$2/100)) | M4: =IF(K4="","",IF(K4=0,0,$I4/$C4*Coeff!D$2/100)) | N4: =IF(L4="","",IF(L4=0,0,$I4/$C4*Coeff!E$2/100)) | O4: =IF(M4="","",IF(M4=0,0,$I4/$C4*Coeff!F$2/100)) | P4: =IF(N4="","",IF(N4=0,0,$I4/$C4*Coeff!G$2/100)) | Q4: =IF(O4="","",IF(O4=0,0,$I4/$C4*Coeff!H$2/100)) | R4: =IF(P4="","",IF(P4=0,0,$I4/$C4*Coeff!I$2/100))
A5: % Dommages mêlée | B5: Do Per Mé | C5: 15 | D5: 1 | E5: =Feuil1!J5 -> 9398 | F5: =E5/C5 -> 626.53333 | G5: =Feuil1!L5 -> 0 | H5: =IF(OR(G5="",G5=0,C5="",C5=0,D5="",D5=0),"",3*G5*C5/D5*Feuil1!$B$2/200+1) | I5: =IF(H5="","",IF(H5=0,"",H5+(SUM($H$2:$H$1004))/2-H5/2)) | J5: =IF(H5="","",IF(H5=0,0,$I5/$C5*Coeff!A$2/100)) | K5: =IF(I5="","",IF(I5=0,0,$I5/$C5*Coeff!B$2/100)) | L5: =IF(J5="","",IF(J5=0,0,$I5/$C5*Coeff!C$2/100)) | M5: =IF(K5="","",IF(K5=0,0,$I5/$C5*Coeff!D$2/100)) | N5: =IF(L5="","",IF(L5=0,0,$I5/$C5*Coeff!E$2/100)) | O5: =IF(M5="","",IF(M5=0,0,$I5/$C5*Coeff!F$2/100)) | P5: =IF(N5="","",IF(N5=0,0,$I5/$C5*Coeff!G$2/100)) | Q5: =IF(O5="","",IF(O5=0,0,$I5/$C5*Coeff!H$2/100)) | R5: =IF(P5="","",IF(P5=0,0,$I5/$C5*Coeff!I$2/100))
A6: % Résistance Air | B6: Ré Per Air | C6: 6 | D6: 1 | E6: =Feuil1!J6 -> 1264 | F6: =E6/C6 -> 210.66667 | G6: =Feuil1!L6 -> 0 | H6: =IF(OR(G6="",G6=0,C6="",C6=0,D6="",D6=0),"",3*G6*C6/D6*Feuil1!$B$2/200+1) | I6: =IF(H6="","",IF(H6=0,"",H6+(SUM($H$2:$H$1004))/2-H6/2)) | J6: =IF(H6="","",IF(H6=0,0,$I6/$C6*Coeff!A$2/100)) | K6: =IF(I6="","",IF(I6=0,0,$I6/$C6*Coeff!B$2/100)) | L6: =IF(J6="","",IF(J6=0,0,$I6/$C6*Coeff!C$2/100)) | M6: =IF(K6="","",IF(K6=0,0,$I6/$C6*Coeff!D$2/100)) | N6: =IF(L6="","",IF(L6=0,0,$I6/$C6*Coeff!E$2/100)) | O6: =IF(M6="","",IF(M6=0,0,$I6/$C6*Coeff!F$2/100)) | P6: =IF(N6="","",IF(N6=0,0,$I6/$C6*Coeff!G$2/100)) | Q6: =IF(O6="","",IF(O6=0,0,$I6/$C6*Coeff!H$2/100)) | R6: =IF(P6="","",IF(P6=0,0,$I6/$C6*Coeff!I$2/100))
A7: % Résistance Distance | B7: Ré Per Di | C7: 10 | D7: 1 | E7: =Feuil1!J7 -> 1898 | F7: =E7/C7 -> 189.8 | G7: =Feuil1!L7 -> 0 | H7: =IF(OR(G7="",G7=0,C7="",C7=0,D7="",D7=0),"",3*G7*C7/D7*Feuil1!$B$2/200+1) | I7: =IF(H7="","",IF(H7=0,"",H7+(SUM($H$2:$H$1004))/2-H7/2)) | J7: =IF(H7="","",IF(H7=0,0,$I7/$C7*Coeff!A$2/100)) | K7: =IF(I7="","",IF(I7=0,0,$I7/$C7*Coeff!B$2/100)) | L7: =IF(J7="","",IF(J7=0,0,$I7/$C7*Coeff!C$2/100)) | M7: =IF(K7="","",IF(K7=0,0,$I7/$C7*Coeff!D$2/100)) | N7: =IF(L7="","",IF(L7=0,0,$I7/$C7*Coeff!E$2/100)) | O7: =IF(M7="","",IF(M7=0,0,$I7/$C7*Coeff!F$2/100)) | P7: =IF(N7="","",IF(N7=0,0,$I7/$C7*Coeff!G$2/100)) | Q7: =IF(O7="","",IF(O7=0,0,$I7/$C7*Coeff!H$2/100)) | R7: =IF(P7="","",IF(P7=0,0,$I7/$C7*Coeff!I$2/100))
A8: % Résistance Eau | B8: Ré Per Eau | C8: 6 | D8: 1 | E8: =Feuil1!J8 -> 1514 | F8: =E8/C8 -> 252.33333 | G8: =Feuil1!L8 -> 0 | H8: =IF(OR(G8="",G8=0,C8="",C8=0,D8="",D8=0),"",3*G8*C8/D8*Feuil1!$B$2/200+1) | I8: =IF(H8="","",IF(H8=0,"",H8+(SUM($H$2:$H$1004))/2-H8/2)) | J8: =IF(H8="","",IF(H8=0,0,$I8/$C8*Coeff!A$2/100)) | K8: =IF(I8="","",IF(I8=0,0,$I8/$C8*Coeff!B$2/100)) | L8: =IF(J8="","",IF(J8=0,0,$I8/$C8*Coeff!C$2/100)) | M8: =IF(K8="","",IF(K8=0,0,$I8/$C8*Coeff!D$2/100)) | N8: =IF(L8="","",IF(L8=0,0,$I8/$C8*Coeff!E$2/100)) | O8: =IF(M8="","",IF(M8=0,0,$I8/$C8*Coeff!F$2/100)) | P8: =IF(N8="","",IF(N8=0,0,$I8/$C8*Coeff!G$2/100)) | Q8: =IF(O8="","",IF(O8=0,0,$I8/$C8*Coeff!H$2/100)) | R8: =IF(P8="","",IF(P8=0,0,$I8/$C8*Coeff!I$2/100))
A9: % Résistance Feu | B9: Ré Per Feu | C9: 6 | D9: 1 | E9: =Feuil1!J9 -> 1051 | F9: =E9/C9 -> 175.16667 | G9: =Feuil1!L9 -> 0 | H9: =IF(OR(G9="",G9=0,C9="",C9=0,D9="",D9=0),"",3*G9*C9/D9*Feuil1!$B$2/200+1) | I9: =IF(H9="","",IF(H9=0,"",H9+(SUM($H$2:$H$1004))/2-H9/2)) | J9: =IF(H9="","",IF(H9=0,0,$I9/$C9*Coeff!A$2/100)) | K9: =IF(I9="","",IF(I9=0,0,$I9/$C9*Coeff!B$2/100)) | L9: =IF(J9="","",IF(J9=0,0,$I9/$C9*Coeff!C$2/100)) | M9: =IF(K9="","",IF(K9=0,0,$I9/$C9*Coeff!D$2/100)) | N9: =IF(L9="","",IF(L9=0,0,$I9/$C9*Coeff!E$2/100)) | O9: =IF(M9="","",IF(M9=0,0,$I9/$C9*Coeff!F$2/100)) | P9: =IF(N9="","",IF(N9=0,0,$I9/$C9*Coeff!G$2/100)) | Q9: =IF(O9="","",IF(O9=0,0,$I9/$C9*Coeff!H$2/100)) | R9: =IF(P9="","",IF(P9=0,0,$I9/$C9*Coeff!I$2/100))
A10: % Résistance Mêlée | B10: Ré Per Mé | C10: 10 | D10: 1 | E10: =Feuil1!J10 -> 3961 | F10: =E10/C10 -> 396.1 | G10: =Feuil1!L10 -> 0 | H10: =IF(OR(G10="",G10=0,C10="",C10=0,D10="",D10=0),"",3*G10*C10/D10*Feuil1!$B$2/200+1) | I10: =IF(H10="","",IF(H10=0,"",H10+(SUM($H$2:$H$1004))/2-H10/2)) | J10: =IF(H10="","",IF(H10=0,0,$I10/$C10*Coeff!A$2/100)) | K10: =IF(I10="","",IF(I10=0,0,$I10/$C10*Coeff!B$2/100)) | L10: =IF(J10="","",IF(J10=0,0,$I10/$C10*Coeff!C$2/100)) | M10: =IF(K10="","",IF(K10=0,0,$I10/$C10*Coeff!D$2/100)) | N10: =IF(L10="","",IF(L10=0,0,$I10/$C10*Coeff!E$2/100)) | O10: =IF(M10="","",IF(M10=0,0,$I10/$C10*Coeff!F$2/100)) | P10: =IF(N10="","",IF(N10=0,0,$I10/$C10*Coeff!G$2/100)) | Q10: =IF(O10="","",IF(O10=0,0,$I10/$C10*Coeff!H$2/100)) | R10: =IF(P10="","",IF(P10=0,0,$I10/$C10*Coeff!I$2/100))
A11: % Résistance Neutre | B11: Ré Per Neutre | C11: 6 | D11: 1 | E11: =Feuil1!J11 -> 1209 | F11: =E11/C11 -> 201.5 | G11: =Feuil1!L11 -> 0 | H11: =IF(OR(G11="",G11=0,C11="",C11=0,D11="",D11=0),"",3*G11*C11/D11*Feuil1!$B$2/200+1) | I11: =IF(H11="","",IF(H11=0,"",H11+(SUM($H$2:$H$1004))/2-H11/2)) | J11: =IF(H11="","",IF(H11=0,0,$I11/$C11*Coeff!A$2/100)) | K11: =IF(I11="","",IF(I11=0,0,$I11/$C11*Coeff!B$2/100)) | L11: =IF(J11="","",IF(J11=0,0,$I11/$C11*Coeff!C$2/100)) | M11: =IF(K11="","",IF(K11=0,0,$I11/$C11*Coeff!D$2/100)) | N11: =IF(L11="","",IF(L11=0,0,$I11/$C11*Coeff!E$2/100)) | O11: =IF(M11="","",IF(M11=0,0,$I11/$C11*Coeff!F$2/100)) | P11: =IF(N11="","",IF(N11=0,0,$I11/$C11*Coeff!G$2/100)) | Q11: =IF(O11="","",IF(O11=0,0,$I11/$C11*Coeff!H$2/100)) | R11: =IF(P11="","",IF(P11=0,0,$I11/$C11*Coeff!I$2/100))
A12: % Résistance Terre | B12: Ré Per Terre | C12: 6 | D12: 1 | E12: =Feuil1!J12 -> 1438 | F12: =E12/C12 -> 239.66667 | G12: =Feuil1!L12 -> 0 | H12: =IF(OR(G12="",G12=0,C12="",C12=0,D12="",D12=0),"",3*G12*C12/D12*Feuil1!$B$2/200+1) | I12: =IF(H12="","",IF(H12=0,"",H12+(SUM($H$2:$H$1004))/2-H12/2)) | J12: =IF(H12="","",IF(H12=0,0,$I12/$C12*Coeff!A$2/100)) | K12: =IF(I12="","",IF(I12=0,0,$I12/$C12*Coeff!B$2/100)) | L12: =IF(J12="","",IF(J12=0,0,$I12/$C12*Coeff!C$2/100)) | M12: =IF(K12="","",IF(K12=0,0,$I12/$C12*Coeff!D$2/100)) | N12: =IF(L12="","",IF(L12=0,0,$I12/$C12*Coeff!E$2/100)) | O12: =IF(M12="","",IF(M12=0,0,$I12/$C12*Coeff!F$2/100)) | P12: =IF(N12="","",IF(N12=0,0,$I12/$C12*Coeff!G$2/100)) | Q12: =IF(O12="","",IF(O12=0,0,$I12/$C12*Coeff!H$2/100)) | R12: =IF(P12="","",IF(P12=0,0,$I12/$C12*Coeff!I$2/100))
A13: Agilité | B13: Age | C13: 1 | D13: 1 | E13: =Feuil1!J13 -> 99 | F13: =E13/C13 -> 99 | G13: =Feuil1!L13 -> 0 | H13: =IF(OR(G13="",G13=0,C13="",C13=0,D13="",D13=0),"",3*G13*C13/D13*Feuil1!$B$2/200+1) | I13: =IF(H13="","",IF(H13=0,"",H13+(SUM($H$2:$H$1004))/2-H13/2)) | J13: =IF(H13="","",IF(H13=0,0,$I13/$C13*Coeff!A$2/100)) | K13: =IF(I13="","",IF(I13=0,0,$I13/$C13*Coeff!B$2/100)) | L13: =IF(J13="","",IF(J13=0,0,$I13/$C13*Coeff!C$2/100)) | M13: =IF(K13="","",IF(K13=0,0,$I13/$C13*Coeff!D$2/100)) | N13: =IF(L13="","",IF(L13=0,0,$I13/$C13*Coeff!E$2/100)) | O13: =IF(M13="","",IF(M13=0,0,$I13/$C13*Coeff!F$2/100)) | P13: =IF(N13="","",IF(N13=0,0,$I13/$C13*Coeff!G$2/100)) | Q13: =IF(O13="","",IF(O13=0,0,$I13/$C13*Coeff!H$2/100)) | R13: =IF(P13="","",IF(P13=0,0,$I13/$C13*Coeff!I$2/100))
... A51: Vitalité | B51: Vi | C51: 1 | D51: 5 | E51: =Feuil1!J51 -> 183 | F51: =E51/C51 -> 183 | G51: =Feuil1!L51 -> 0 | H51: =IF(OR(G51="",G51=0,C51="",C51=0,D51="",D51=0),"",3*G51*C51/D51*Feuil1!$B$2/200+1) | I51: =IF(H51="","",IF(H51=0,"",H51+(SUM($H$2:$H$1004))/2-H51/2)) | J51: =IF(H51="","",IF(H51=0,0,$I51/$C51*Coeff!A$2/100)) | K51: =IF(I51="","",IF(I51=0,0,$I51/$C51*Coeff!B$2/100)) | L51: =IF(J51="","",IF(J51=0,0,$I51/$C51*Coeff!C$2/100)) | M51: =IF(K51="","",IF(K51=0,0,$I51/$C51*Coeff!D$2/100)) | N51: =IF(L51="","",IF(L51=0,0,$I51/$C51*Coeff!E$2/100)) | O51: =IF(M51="","",IF(M51=0,0,$I51/$C51*Coeff!F$2/100)) | P51: =IF(N51="","",IF(N51=0,0,$I51/$C51*Coeff!G$2/100)) | Q51: =IF(O51="","",IF(O51=0,0,$I51/$C51*Coeff!H$2/100)) | R51: =IF(P51="","",IF(P51=0,0,$I51/$C51*Coeff!I$2/100))

Sheet Value
A1: Nom de la stat | B1: Nom de rune | C1: Poids Rune | D1: Stat par rune | E1: Prix Rune | F1: Prix / poids runes | G1: Nombre de stats | H1: Poids ligne | I1: Poids focus | J1: ="Valeur rune a " & TEXT(Coeff!A2,"0,00") & "%" -> Valeur rune a 100,00% | K1: ="Valeur rune a " & TEXT(Coeff!B2,"0,00") & "%" -> Valeur rune a 14,00% | L1: ="Valeur rune a " & TEXT(Coeff!C2,"0,00") & "%" -> Valeur rune a 13,99% | M1: ="Valeur rune a " & TEXT(Coeff!D2,"0,00") & "%" -> Valeur rune a 13,99% | N1: ="Valeur rune a " & TEXT(Coeff!E2,"0,00") & "%" -> Valeur rune a 13,98% | O1: ="Valeur rune a " & TEXT(Coeff!F2,"0,00") & "%" -> Valeur rune a 13,95% | P1: ="Valeur rune a " & TEXT(Coeff!G2,"0,00") & "%" -> Valeur rune a 13,50% | Q1: ="Valeur rune a " & TEXT(Coeff!H2,"0,00") & "%" -> Valeur rune a 10,23% | R1: ="Valeur rune a " & TEXT(Coeff!I2,"0,00") & "%" -> Valeur rune a 13,50%
A2: % Dommages aux sorts | B2: Do Per So | C2: 15 | D2: 1 | E2: =Feuil1!J2 -> 27934 | F2: =E2/C2 -> 1862.2667 | G2: =Feuil1!L2 -> 0 | H2: =IF(OR(G2="",G2=0,C2="",C2=0,D2="",D2=0),"",3*G2*C2/D2*Feuil1!$B$2/200+1) | I2: =IF(H2="","",IF(H2=0,"",H2+(SUM($H$2:$H$1004))/2-H2/2)) | J2: =IF(Qte!J2="","",IF(Qte!J2=0,"",IF($E2="","",IF($E2=0,"",Qte!J2*$E2)))) | K2: =IF(Qte!K2="","",IF(Qte!K2=0,"",IF($E2="","",IF($E2=0,"",Qte!K2*$E2)))) | L2: =IF(Qte!L2="","",IF(Qte!L2=0,"",IF($E2="","",IF($E2=0,"",Qte!L2*$E2)))) | M2: =IF(Qte!M2="","",IF(Qte!M2=0,"",IF($E2="","",IF($E2=0,"",Qte!M2*$E2)))) | N2: =IF(Qte!N2="","",IF(Qte!N2=0,"",IF($E2="","",IF($E2=0,"",Qte!N2*$E2)))) | O2: =IF(Qte!O2="","",IF(Qte!O2=0,"",IF($E2="","",IF($E2=0,"",Qte!O2*$E2)))) | P2: =IF(Qte!P2="","",IF(Qte!P2=0,"",IF($E2="","",IF($E2=0,"",Qte!P2*$E2)))) | Q2: =IF(Qte!Q2="","",IF(Qte!Q2=0,"",IF($E2="","",IF($E2=0,"",Qte!Q2*$E2)))) | R2: =IF(Qte!R2="","",IF(Qte!R2=0,"",IF($E2="","",IF($E2=0,"",Qte!R2*$E2))))
A3: % Dommages d'armes | B3: Do Per Ar | C3: 15 | D3: 1 | E3: =Feuil1!J3 -> 6321 | F3: =E3/C3 -> 421.4 | G3: =Feuil1!L3 -> 0 | H3: =IF(OR(G3="",G3=0,C3="",C3=0,D3="",D3=0),"",3*G3*C3/D3*Feuil1!$B$2/200+1) | I3: =IF(H3="","",IF(H3=0,"",H3+(SUM($H$2:$H$1004))/2-H3/2)) | J3: =IF(Qte!J3="","",IF(Qte!J3=0,"",IF($E3="","",IF($E3=0,"",Qte!J3*$E3)))) | K3: =IF(Qte!K3="","",IF(Qte!K3=0,"",IF($E3="","",IF($E3=0,"",Qte!K3*$E3)))) | L3: =IF(Qte!L3="","",IF(Qte!L3=0,"",IF($E3="","",IF($E3=0,"",Qte!L3*$E3)))) | M3: =IF(Qte!M3="","",IF(Qte!M3=0,"",IF($E3="","",IF($E3=0,"",Qte!M3*$E3)))) | N3: =IF(Qte!N3="","",IF(Qte!N3=0,"",IF($E3="","",IF($E3=0,"",Qte!N3*$E3)))) | O3: =IF(Qte!O3="","",IF(Qte!O3=0,"",IF($E3="","",IF($E3=0,"",Qte!O3*$E3)))) | P3: =IF(Qte!P3="","",IF(Qte!P3=0,"",IF($E3="","",IF($E3=0,"",Qte!P3*$E3)))) | Q3: =IF(Qte!Q3="","",IF(Qte!Q3=0,"",IF($E3="","",IF($E3=0,"",Qte!Q3*$E3)))) | R3: =IF(Qte!R3="","",IF(Qte!R3=0,"",IF($E3="","",IF($E3=0,"",Qte!R3*$E3))))
A4: % Dommages distance | B4: Do Per Di | C4: 15 | D4: 1 | E4: =Feuil1!J4 -> 29031 | F4: =E4/C4 -> 1935.4 | G4: =Feuil1!L4 -> 0 | H4: =IF(OR(G4="",G4=0,C4="",C4=0,D4="",D4=0),"",3*G4*C4/D4*Feuil1!$B$2/200+1) | I4: =IF(H4="","",IF(H4=0,"",H4+(SUM($H$2:$H$1004))/2-H4/2)) | J4: =IF(Qte!J4="","",IF(Qte!J4=0,"",IF($E4="","",IF($E4=0,"",Qte!J4*$E4)))) | K4: =IF(Qte!K4="","",IF(Qte!K4=0,"",IF($E4="","",IF($E4=0,"",Qte!K4*$E4)))) | L4: =IF(Qte!L4="","",IF(Qte!L4=0,"",IF($E4="","",IF($E4=0,"",Qte!L4*$E4)))) | M4: =IF(Qte!M4="","",IF(Qte!M4=0,"",IF($E4="","",IF($E4=0,"",Qte!M4*$E4)))) | N4: =IF(Qte!N4="","",IF(Qte!N4=0,"",IF($E4="","",IF($E4=0,"",Qte!N4*$E4)))) | O4: =IF(Qte!O4="","",IF(Qte!O4=0,"",IF($E4="","",IF($E4=0,"",Qte!O4*$E4)))) | P4: =IF(Qte!P4="","",IF(Qte!P4=0,"",IF($E4="","",IF($E4=0,"",Qte!P4*$E4)))) | Q4: =IF(Qte!Q4="","",IF(Qte!Q4=0,"",IF($E4="","",IF($E4=0,"",Qte!Q4*$E4)))) | R4: =IF(Qte!R4="","",IF(Qte!R4=0,"",IF($E4="","",IF($E4=0,"",Qte!R4*$E4))))
A5: % Dommages mêlée | B5: Do Per Mé | C5: 15 | D5: 1 | E5: =Feuil1!J5 -> 9398 | F5: =E5/C5 -> 626.53333 | G5: =Feuil1!L5 -> 0 | H5: =IF(OR(G5="",G5=0,C5="",C5=0,D5="",D5=0),"",3*G5*C5/D5*Feuil1!$B$2/200+1) | I5: =IF(H5="","",IF(H5=0,"",H5+(SUM($H$2:$H$1004))/2-H5/2)) | J5: =IF(Qte!J5="","",IF(Qte!J5=0,"",IF($E5="","",IF($E5=0,"",Qte!J5*$E5)))) | K5: =IF(Qte!K5="","",IF(Qte!K5=0,"",IF($E5="","",IF($E5=0,"",Qte!K5*$E5)))) | L5: =IF(Qte!L5="","",IF(Qte!L5=0,"",IF($E5="","",IF($E5=0,"",Qte!L5*$E5)))) | M5: =IF(Qte!M5="","",IF(Qte!M5=0,"",IF($E5="","",IF($E5=0,"",Qte!M5*$E5)))) | N5: =IF(Qte!N5="","",IF(Qte!N5=0,"",IF($E5="","",IF($E5=0,"",Qte!N5*$E5)))) | O5: =IF(Qte!O5="","",IF(Qte!O5=0,"",IF($E5="","",IF($E5=0,"",Qte!O5*$E5)))) | P5: =IF(Qte!P5="","",IF(Qte!P5=0,"",IF($E5="","",IF($E5=0,"",Qte!P5*$E5)))) | Q5: =IF(Qte!Q5="","",IF(Qte!Q5=0,"",IF($E5="","",IF($E5=0,"",Qte!Q5*$E5)))) | R5: =IF(Qte!R5="","",IF(Qte!R5=0,"",IF($E5="","",IF($E5=0,"",Qte!R5*$E5))))
A6: % Résistance Air | B6: Ré Per Air | C6: 6 | D6: 1 | E6: =Feuil1!J6 -> 1264 | F6: =E6/C6 -> 210.66667 | G6: =Feuil1!L6 -> 0 | H6: =IF(OR(G6="",G6=0,C6="",C6=0,D6="",D6=0),"",3*G6*C6/D6*Feuil1!$B$2/200+1) | I6: =IF(H6="","",IF(H6=0,"",H6+(SUM($H$2:$H$1004))/2-H6/2)) | J6: =IF(Qte!J6="","",IF(Qte!J6=0,"",IF($E6="","",IF($E6=0,"",Qte!J6*$E6)))) | K6: =IF(Qte!K6="","",IF(Qte!K6=0,"",IF($E6="","",IF($E6=0,"",Qte!K6*$E6)))) | L6: =IF(Qte!L6="","",IF(Qte!L6=0,"",IF($E6="","",IF($E6=0,"",Qte!L6*$E6)))) | M6: =IF(Qte!M6="","",IF(Qte!M6=0,"",IF($E6="","",IF($E6=0,"",Qte!M6*$E6)))) | N6: =IF(Qte!N6="","",IF(Qte!N6=0,"",IF($E6="","",IF($E6=0,"",Qte!N6*$E6)))) | O6: =IF(Qte!O6="","",IF(Qte!O6=0,"",IF($E6="","",IF($E6=0,"",Qte!O6*$E6)))) | P6: =IF(Qte!P6="","",IF(Qte!P6=0,"",IF($E6="","",IF($E6=0,"",Qte!P6*$E6)))) | Q6: =IF(Qte!Q6="","",IF(Qte!Q6=0,"",IF($E6="","",IF($E6=0,"",Qte!Q6*$E6)))) | R6: =IF(Qte!R6="","",IF(Qte!R6=0,"",IF($E6="","",IF($E6=0,"",Qte!R6*$E6))))
A7: % Résistance Distance | B7: Ré Per Di | C7: 10 | D7: 1 | E7: =Feuil1!J7 -> 1898 | F7: =E7/C7 -> 189.8 | G7: =Feuil1!L7 -> 0 | H7: =IF(OR(G7="",G7=0,C7="",C7=0,D7="",D7=0),"",3*G7*C7/D7*Feuil1!$B$2/200+1) | I7: =IF(H7="","",IF(H7=0,"",H7+(SUM($H$2:$H$1004))/2-H7/2)) | J7: =IF(Qte!J7="","",IF(Qte!J7=0,"",IF($E7="","",IF($E7=0,"",Qte!J7*$E7)))) | K7: =IF(Qte!K7="","",IF(Qte!K7=0,"",IF($E7="","",IF($E7=0,"",Qte!K7*$E7)))) | L7: =IF(Qte!L7="","",IF(Qte!L7=0,"",IF($E7="","",IF($E7=0,"",Qte!L7*$E7)))) | M7: =IF(Qte!M7="","",IF(Qte!M7=0,"",IF($E7="","",IF($E7=0,"",Qte!M7*$E7)))) | N7: =IF(Qte!N7="","",IF(Qte!N7=0,"",IF($E7="","",IF($E7=0,"",Qte!N7*$E7)))) | O7: =IF(Qte!O7="","",IF(Qte!O7=0,"",IF($E7="","",IF($E7=0,"",Qte!O7*$E7)))) | P7: =IF(Qte!P7="","",IF(Qte!P7=0,"",IF($E7="","",IF($E7=0,"",Qte!P7*$E7)))) | Q7: =IF(Qte!Q7="","",IF(Qte!Q7=0,"",IF($E7="","",IF($E7=0,"",Qte!Q7*$E7)))) | R7: =IF(Qte!R7="","",IF(Qte!R7=0,"",IF($E7="","",IF($E7=0,"",Qte!R7*$E7))))
A8: % Résistance Eau | B8: Ré Per Eau | C8: 6 | D8: 1 | E8: =Feuil1!J8 -> 1514 | F8: =E8/C8 -> 252.33333 | G8: =Feuil1!L8 -> 0 | H8: =IF(OR(G8="",G8=0,C8="",C8=0,D8="",D8=0),"",3*G8*C8/D8*Feuil1!$B$2/200+1) | I8: =IF(H8="","",IF(H8=0,"",H8+(SUM($H$2:$H$1004))/2-H8/2)) | J8: =IF(Qte!J8="","",IF(Qte!J8=0,"",IF($E8="","",IF($E8=0,"",Qte!J8*$E8)))) | K8: =IF(Qte!K8="","",IF(Qte!K8=0,"",IF($E8="","",IF($E8=0,"",Qte!K8*$E8)))) | L8: =IF(Qte!L8="","",IF(Qte!L8=0,"",IF($E8="","",IF($E8=0,"",Qte!L8*$E8)))) | M8: =IF(Qte!M8="","",IF(Qte!M8=0,"",IF($E8="","",IF($E8=0,"",Qte!M8*$E8)))) | N8: =IF(Qte!N8="","",IF(Qte!N8=0,"",IF($E8="","",IF($E8=0,"",Qte!N8*$E8)))) | O8: =IF(Qte!O8="","",IF(Qte!O8=0,"",IF($E8="","",IF($E8=0,"",Qte!O8*$E8)))) | P8: =IF(Qte!P8="","",IF(Qte!P8=0,"",IF($E8="","",IF($E8=0,"",Qte!P8*$E8)))) | Q8: =IF(Qte!Q8="","",IF(Qte!Q8=0,"",IF($E8="","",IF($E8=0,"",Qte!Q8*$E8)))) | R8: =IF(Qte!R8="","",IF(Qte!R8=0,"",IF($E8="","",IF($E8=0,"",Qte!R8*$E8))))
A9: % Résistance Feu | B9: Ré Per Feu | C9: 6 | D9: 1 | E9: =Feuil1!J9 -> 1051 | F9: =E9/C9 -> 175.16667 | G9: =Feuil1!L9 -> 0 | H9: =IF(OR(G9="",G9=0,C9="",C9=0,D9="",D9=0),"",3*G9*C9/D9*Feuil1!$B$2/200+1) | I9: =IF(H9="","",IF(H9=0,"",H9+(SUM($H$2:$H$1004))/2-H9/2)) | J9: =IF(Qte!J9="","",IF(Qte!J9=0,"",IF($E9="","",IF($E9=0,"",Qte!J9*$E9)))) | K9: =IF(Qte!K9="","",IF(Qte!K9=0,"",IF($E9="","",IF($E9=0,"",Qte!K9*$E9)))) | L9: =IF(Qte!L9="","",IF(Qte!L9=0,"",IF($E9="","",IF($E9=0,"",Qte!L9*$E9)))) | M9: =IF(Qte!M9="","",IF(Qte!M9=0,"",IF($E9="","",IF($E9=0,"",Qte!M9*$E9)))) | N9: =IF(Qte!N9="","",IF(Qte!N9=0,"",IF($E9="","",IF($E9=0,"",Qte!N9*$E9)))) | O9: =IF(Qte!O9="","",IF(Qte!O9=0,"",IF($E9="","",IF($E9=0,"",Qte!O9*$E9)))) | P9: =IF(Qte!P9="","",IF(Qte!P9=0,"",IF($E9="","",IF($E9=0,"",Qte!P9*$E9)))) | Q9: =IF(Qte!Q9="","",IF(Qte!Q9=0,"",IF($E9="","",IF($E9=0,"",Qte!Q9*$E9)))) | R9: =IF(Qte!R9="","",IF(Qte!R9=0,"",IF($E9="","",IF($E9=0,"",Qte!R9*$E9))))
A10: % Résistance Mêlée | B10: Ré Per Mé | C10: 10 | D10: 1 | E10: =Feuil1!J10 -> 3961 | F10: =E10/C10 -> 396.1 | G10: =Feuil1!L10 -> 0 | H10: =IF(OR(G10="",G10=0,C10="",C10=0,D10="",D10=0),"",3*G10*C10/D10*Feuil1!$B$2/200+1) | I10: =IF(H10="","",IF(H10=0,"",H10+(SUM($H$2:$H$1004))/2-H10/2)) | J10: =IF(Qte!J10="","",IF(Qte!J10=0,"",IF($E10="","",IF($E10=0,"",Qte!J10*$E10)))) | K10: =IF(Qte!K10="","",IF(Qte!K10=0,"",IF($E10="","",IF($E10=0,"",Qte!K10*$E10)))) | L10: =IF(Qte!L10="","",IF(Qte!L10=0,"",IF($E10="","",IF($E10=0,"",Qte!L10*$E10)))) | M10: =IF(Qte!M10="","",IF(Qte!M10=0,"",IF($E10="","",IF($E10=0,"",Qte!M10*$E10)))) | N10: =IF(Qte!N10="","",IF(Qte!N10=0,"",IF($E10="","",IF($E10=0,"",Qte!N10*$E10)))) | O10: =IF(Qte!O10="","",IF(Qte!O10=0,"",IF($E10="","",IF($E10=0,"",Qte!O10*$E10)))) | P10: =IF(Qte!P10="","",IF(Qte!P10=0,"",IF($E10="","",IF($E10=0,"",Qte!P10*$E10)))) | Q10: =IF(Qte!Q10="","",IF(Qte!Q10=0,"",IF($E10="","",IF($E10=0,"",Qte!Q10*$E10)))) | R10: =IF(Qte!R10="","",IF(Qte!R10=0,"",IF($E10="","",IF($E10=0,"",Qte!R10*$E10))))
A11: % Résistance Neutre | B11: Ré Per Neutre | C11: 6 | D11: 1 | E11: =Feuil1!J11 -> 1209 | F11: =E11/C11 -> 201.5 | G11: =Feuil1!L11 -> 0 | H11: =IF(OR(G11="",G11=0,C11="",C11=0,D11="",D11=0),"",3*G11*C11/D11*Feuil1!$B$2/200+1) | I11: =IF(H11="","",IF(H11=0,"",H11+(SUM($H$2:$H$1004))/2-H11/2)) | J11: =IF(Qte!J11="","",IF(Qte!J11=0,"",IF($E11="","",IF($E11=0,"",Qte!J11*$E11)))) | K11: =IF(Qte!K11="","",IF(Qte!K11=0,"",IF($E11="","",IF($E11=0,"",Qte!K11*$E11)))) | L11: =IF(Qte!L11="","",IF(Qte!L11=0,"",IF($E11="","",IF($E11=0,"",Qte!L11*$E11)))) | M11: =IF(Qte!M11="","",IF(Qte!M11=0,"",IF($E11="","",IF($E11=0,"",Qte!M11*$E11)))) | N11: =IF(Qte!N11="","",IF(Qte!N11=0,"",IF($E11="","",IF($E11=0,"",Qte!N11*$E11)))) | O11: =IF(Qte!O11="","",IF(Qte!O11=0,"",IF($E11="","",IF($E11=0,"",Qte!O11*$E11)))) | P11: =IF(Qte!P11="","",IF(Qte!P11=0,"",IF($E11="","",IF($E11=0,"",Qte!P11*$E11)))) | Q11: =IF(Qte!Q11="","",IF(Qte!Q11=0,"",IF($E11="","",IF($E11=0,"",Qte!Q11*$E11)))) | R11: =IF(Qte!R11="","",IF(Qte!R11=0,"",IF($E11="","",IF($E11=0,"",Qte!R11*$E11))))
A12: % Résistance Terre | B12: Ré Per Terre | C12: 6 | D12: 1 | E12: =Feuil1!J12 -> 1438 | F12: =E12/C12 -> 239.66667 | G12: =Feuil1!L12 -> 0 | H12: =IF(OR(G12="",G12=0,C12="",C12=0,D12="",D12=0),"",3*G12*C12/D12*Feuil1!$B$2/200+1) | I12: =IF(H12="","",IF(H12=0,"",H12+(SUM($H$2:$H$1004))/2-H12/2)) | J12: =IF(Qte!J12="","",IF(Qte!J12=0,"",IF($E12="","",IF($E12=0,"",Qte!J12*$E12)))) | K12: =IF(Qte!K12="","",IF(Qte!K12=0,"",IF($E12="","",IF($E12=0,"",Qte!K12*$E12)))) | L12: =IF(Qte!L12="","",IF(Qte!L12=0,"",IF($E12="","",IF($E12=0,"",Qte!L12*$E12)))) | M12: =IF(Qte!M12="","",IF(Qte!M12=0,"",IF($E12="","",IF($E12=0,"",Qte!M12*$E12)))) | N12: =IF(Qte!N12="","",IF(Qte!N12=0,"",IF($E12="","",IF($E12=0,"",Qte!N12*$E12)))) | O12: =IF(Qte!O12="","",IF(Qte!O12=0,"",IF($E12="","",IF($E12=0,"",Qte!O12*$E12)))) | P12: =IF(Qte!P12="","",IF(Qte!P12=0,"",IF($E12="","",IF($E12=0,"",Qte!P12*$E12)))) | Q12: =IF(Qte!Q12="","",IF(Qte!Q12=0,"",IF($E12="","",IF($E12=0,"",Qte!Q12*$E12)))) | R12: =IF(Qte!R12="","",IF(Qte!R12=0,"",IF($E12="","",IF($E12=0,"",Qte!R12*$E12))))
A13: Agilité | B13: Age | C13: 1 | D13: 1 | E13: =Feuil1!J13 -> 99 | F13: =E13/C13 -> 99 | G13: =Feuil1!L13 -> 0 | H13: =IF(OR(G13="",G13=0,C13="",C13=0,D13="",D13=0),"",3*G13*C13/D13*Feuil1!$B$2/200+1) | I13: =IF(H13="","",IF(H13=0,"",H13+(SUM($H$2:$H$1004))/2-H13/2)) | J13: =IF(Qte!J13="","",IF(Qte!J13=0,"",IF($E13="","",IF($E13=0,"",Qte!J13*$E13)))) | K13: =IF(Qte!K13="","",IF(Qte!K13=0,"",IF($E13="","",IF($E13=0,"",Qte!K13*$E13)))) | L13: =IF(Qte!L13="","",IF(Qte!L13=0,"",IF($E13="","",IF($E13=0,"",Qte!L13*$E13)))) | M13: =IF(Qte!M13="","",IF(Qte!M13=0,"",IF($E13="","",IF($E13=0,"",Qte!M13*$E13)))) | N13: =IF(Qte!N13="","",IF(Qte!N13=0,"",IF($E13="","",IF($E13=0,"",Qte!N13*$E13)))) | O13: =IF(Qte!O13="","",IF(Qte!O13=0,"",IF($E13="","",IF($E13=0,"",Qte!O13*$E13)))) | P13: =IF(Qte!P13="","",IF(Qte!P13=0,"",IF($E13="","",IF($E13=0,"",Qte!P13*$E13)))) | Q13: =IF(Qte!Q13="","",IF(Qte!Q13=0,"",IF($E13="","",IF($E13=0,"",Qte!Q13*$E13)))) | R13: =IF(Qte!R13="","",IF(Qte!R13=0,"",IF($E13="","",IF($E13=0,"",Qte!R13*$E13))))
... A51: Vitalité | B51: Vi | C51: 1 | D51: 5 | E51: =Feuil1!J51 -> 183 | F51: =E51/C51 -> 183 | G51: =Feuil1!L51 -> 0 | H51: =IF(OR(G51="",G51=0,C51="",C51=0,D51="",D51=0),"",3*G51*C51/D51*Feuil1!$B$2/200+1) | I51: =IF(H51="","",IF(H51=0,"",H51+(SUM($H$2:$H$1004))/2-H51/2)) | J51: =IF(Qte!J51="","",IF(Qte!J51=0,"",IF($E51="","",IF($E51=0,"",Qte!J51*$E51)))) | K51: =IF(Qte!K51="","",IF(Qte!K51=0,"",IF($E51="","",IF($E51=0,"",Qte!K51*$E51)))) | L51: =IF(Qte!L51="","",IF(Qte!L51=0,"",IF($E51="","",IF($E51=0,"",Qte!L51*$E51)))) | M51: =IF(Qte!M51="","",IF(Qte!M51=0,"",IF($E51="","",IF($E51=0,"",Qte!M51*$E51)))) | N51: =IF(Qte!N51="","",IF(Qte!N51=0,"",IF($E51="","",IF($E51=0,"",Qte!N51*$E51)))) | O51: =IF(Qte!O51="","",IF(Qte!O51=0,"",IF($E51="","",IF($E51=0,"",Qte!O51*$E51)))) | P51: =IF(Qte!P51="","",IF(Qte!P51=0,"",IF($E51="","",IF($E51=0,"",Qte!P51*$E51)))) | Q51: =IF(Qte!Q51="","",IF(Qte!Q51=0,"",IF($E51="","",IF($E51=0,"",Qte!Q51*$E51)))) | R51: =IF(Qte!R51="","",IF(Qte!R51=0,"",IF($E51="","",IF($E51=0,"",Qte!R51*$E51))))

Sheet PercentDiff
A1: Nom de la stat | B1: Nom de rune | C1: Poids Rune | D1: Stat par rune | E1: Prix Rune | F1: Prix / poids runes | G1: Nombre de stats | H1: Poids ligne | I1: Poids focus | J1: ="% de rentabilité a " & TEXT(Coeff!A2,"0,00") & "%" -> % de rentabilité a 100,00% | K1: ="% de rentabilité a " & TEXT(Coeff!B2,"0,00") & "%" -> % de rentabilité a 14,00% | L1: ="% de rentabilité a " & TEXT(Coeff!C2,"0,00") & "%" -> % de rentabilité a 13,99% | M1: ="% de rentabilité a " & TEXT(Coeff!D2,"0,00") & "%" -> % de rentabilité a 13,99% | N1: ="% de rentabilité a " & TEXT(Coeff!E2,"0,00") & "%" -> % de rentabilité a 13,98% | O1: ="% de rentabilité a " & TEXT(Coeff!F2,"0,00") & "%" -> % de rentabilité a 13,95% | P1: ="% de rentabilité a " & TEXT(Coeff!G2,"0,00") & "%" -> % de rentabilité a 13,50% | Q1: ="% de rentabilité a " & TEXT(Coeff!H2,"0,00") & "%" -> % de rentabilité a 10,23% | R1: ="% de rentabilité a " & TEXT(Coeff!I2,"0,00") & "%" -> % de rentabilité a 13,50%
A2: % Dommages aux sorts | B2: Do Per So | C2: 15 | D2: 1 | E2: =Feuil1!J2 -> 27934 | F2: =E2/C2 -> 1862.2667 | G2: =Feuil1!L2 -> 0 | H2: =IF(OR(G2="",G2=0,C2="",C2=0,D2="",D2=0),"",3*G2*C2/D2*Feuil1!$B$2/200+1) | I2: =IF(H2="","",IF(H2=0,"",H2+(SUM($H$2:$H$1004))/2-H2/2)) | J2: =IF(Value!J2="","",IF(Value!J2=0,"",(Value!J2*100/Feuil1!$C$2-100)/100)) | K2: =IF(Value!K2="","",IF(Value!K2=0,"",(Value!K2*100/Feuil1!$C$2-100)/100)) | L2: =IF(Value!L2="","",IF(Value!L2=0,"",(Value!L2*100/Feuil1!$C$2-100)/100)) | M2: =IF(Value!M2="","",IF(Value!M2=0,"",(Value!M2*100/Feuil1!$C$2-100)/100)) | N2: =IF(Value!N2="","",IF(Value!N2=0,"",(Value!N2*100/Feuil1!$C$2-100)/100)) | O2: =IF(Value!O2="","",IF(Value!O2=0,"",(Value!O2*100/Feuil1!$C$2-100)/100)) | P2: =IF(Value!P2="","",IF(Value!P2=0,"",(Value!P2*100/Feuil1!$C$2-100)/100)) | Q2: =IF(Value!Q2="","",IF(Value!Q2=0,"",(Value!Q2*100/Feuil1!$C$2-100)/100)) | R2: =IF(Value!R2="","",IF(Value!R2=0,"",(Value!R2*100/Feuil1!$C$2-100)/100))
A3: % Dommages d'armes | B3: Do Per Ar | C3: 15 | D3: 1 | E3: =Feuil1!J3 -> 6321 | F3: =E3/C3 -> 421.4 | G3: =Feuil1!L3 -> 0 | H3: =IF(OR(G3="",G3=0,C3="",C3=0,D3="",D3=0),"",3*G3*C3/D3*Feuil1!$B$2/200+1) | I3: =IF(H3="","",IF(H3=0,"",H3+(SUM($H$2:$H$1004))/2-H3/2)) | J3: =IF(Value!J3="","",IF(Value!J3=0,"",(Value!J3*100/Feuil1!$C$2-100)/100)) | K3: =IF(Value!K3="","",IF(Value!K3=0,"",(Value!K3*100/Feuil1!$C$2-100)/100)) | L3: =IF(Value!L3="","",IF(Value!L3=0,"",(Value!L3*100/Feuil1!$C$2-100)/100)) | M3: =IF(Value!M3="","",IF(Value!M3=0,"",(Value!M3*100/Feuil1!$C$2-100)/100)) | N3: =IF(Value!N3="","",IF(Value!N3=0,"",(Value!N3*100/Feuil1!$C$2-100)/100)) | O3: =IF(Value!O3="","",IF(Value!O3=0,"",(Value!O3*100/Feuil1!$C$2-100)/100)) | P3: =IF(Value!P3="","",IF(Value!P3=0,"",(Value!P3*100/Feuil1!$C$2-100)/100)) | Q3: =IF(Value!Q3="","",IF(Value!Q3=0,"",(Value!Q3*100/Feuil1!$C$2-100)/100)) | R3: =IF(Value!R3="","",IF(Value!R3=0,"",(Value!R3*100/Feuil1!$C$2-100)/100))
A4: % Dommages distance | B4: Do Per Di | C4: 15 | D4: 1 | E4: =Feuil1!J4 -> 29031 | F4: =E4/C4 -> 1935.4 | G4: =Feuil1!L4 -> 0 | H4: =IF(OR(G4="",G4=0,C4="",C4=0,D4="",D4=0),"",3*G4*C4/D4*Feuil1!$B$2/200+1) | I4: =IF(H4="","",IF(H4=0,"",H4+(SUM($H$2:$H$1004))/2-H4/2)) | J4: =IF(Value!J4="","",IF(Value!J4=0,"",(Value!J4*100/Feuil1!$C$2-100)/100)) | K4: =IF(Value!K4="","",IF(Value!K4=0,"",(Value!K4*100/Feuil1!$C$2-100)/100)) | L4: =IF(Value!L4="","",IF(Value!L4=0,"",(Value!L4*100/Feuil1!$C$2-100)/100)) | M4: =IF(Value!M4="","",IF(Value!M4=0,"",(Value!M4*100/Feuil1!$C$2-100)/100)) | N4: =IF(Value!N4="","",IF(Value!N4=0,"",(Value!N4*100/Feuil1!$C$2-100)/100)) | O4: =IF(Value!O4="","",IF(Value!O4=0,"",(Value!O4*100/Feuil1!$C$2-100)/100)) | P4: =IF(Value!P4="","",IF(Value!P4=0,"",(Value!P4*100/Feuil1!$C$2-100)/100)) | Q4: =IF(Value!Q4="","",IF(Value!Q4=0,"",(Value!Q4*100/Feuil1!$C$2-100)/100)) | R4: =IF(Value!R4="","",IF(Value!R4=0,"",(Value!R4*100/Feuil1!$C$2-100)/100))
A5: % Dommages mêlée | B5: Do Per Mé | C5: 15 | D5: 1 | E5: =Feuil1!J5 -> 9398 | F5: =E5/C5 -> 626.53333 | G5: =Feuil1!L5 -> 0 | H5: =IF(OR(G5="",G5=0,C5="",C5=0,D5="",D5=0),"",3*G5*C5/D5*Feuil1!$B$2/200+1) | I5: =IF(H5="","",IF(H5=0,"",H5+(SUM($H$2:$H$1004))/2-H5/2)) | J5: =IF(Value!J5="","",IF(Value!J5=0,"",(Value!J5*100/Feuil1!$C$2-100)/100)) | K5: =IF(Value!K5="","",IF(Value!K5=0,"",(Value!K5*100/Feuil1!$C$2-100)/100)) | L5: =IF(Value!L5="","",IF(Value!L5=0,"",(Value!L5*100/Feuil1!$C$2-100)/100)) | M5: =IF(Value!M5="","",IF(Value!M5=0,"",(Value!M5*100/Feuil1!$C$2-100)/100)) | N5: =IF(Value!N5="","",IF(Value!N5=0,"",(Value!N5*100/Feuil1!$C$2-100)/100)) | O5: =IF(Value!O5="","",IF(Value!O5=0,"",(Value!O5*100/Feuil1!$C$2-100)/100)) | P5: =IF(Value!P5="","",IF(Value!P5=0,"",(Value!P5*100/Feuil1!$C$2-100)/100)) | Q5: =IF(Value!Q5="","",IF(Value!Q5=0,"",(Value!Q5*100/Feuil1!$C$2-100)/100)) | R5: =IF(Value!R5="","",IF(Value!R5=0,"",(Value!R5*100/Feuil1!$C$2-100)/100))
A6: % Résistance Air | B6: Ré Per Air | C6: 6 | D6: 1 | E6: =Feuil1!J6 -> 1264 | F6: =E6/C6 -> 210.66667 | G6: =Feuil1!L6 -> 0 | H6: =IF(OR(G6="",G6=0,C6="",C6=0,D6="",D6=0),"",3*G6*C6/D6*Feuil1!$B$2/200+1) | I6: =IF(H6="","",IF(H6=0,"",H6+(SUM($H$2:$H$1004))/2-H6/2)) | J6: =IF(Value!J6="","",IF(Value!J6=0,"",(Value!J6*100/Feuil1!$C$2-100)/100)) | K6: =IF(Value!K6="","",IF(Value!K6=0,"",(Value!K6*100/Feuil1!$C$2-100)/100)) | L6: =IF(Value!L6="","",IF(Value!L6=0,"",(Value!L6*100/Feuil1!$C$2-100)/100)) | M6: =IF(Value!M6="","",IF(Value!M6=0,"",(Value!M6*100/Feuil1!$C$2-100)/100)) | N6: =IF(Value!N6="","",IF(Value!N6=0,"",(Value!N6*100/Feuil1!$C$2-100)/100)) | O6: =IF(Value!O6="","",IF(Value!O6=0,"",(Value!O6*100/Feuil1!$C$2-100)/100)) | P6: =IF(Value!P6="","",IF(Value!P6=0,"",(Value!P6*100/Feuil1!$C$2-100)/100)) | Q6: =IF(Value!Q6="","",IF(Value!Q6=0,"",(Value!Q6*100/Feuil1!$C$2-100)/100)) | R6: =IF(Value!R6="","",IF(Value!R6=0,"",(Value!R6*100/Feuil1!$C$2-100)/100))
A7: % Résistance Distance | B7: Ré Per Di | C7: 10 | D7: 1 | E7: =Feuil1!J7 -> 1898 | F7: =E7/C7 -> 189.8 | G7: =Feuil1!L7 -> 0 | H7: =IF(OR(G7="",G7=0,C7="",C7=0,D7="",D7=0),"",3*G7*C7/D7*Feuil1!$B$2/200+1) | I7: =IF(H7="","",IF(H7=0,"",H7+(SUM($H$2:$H$1004))/2-H7/2)) | J7: =IF(Value!J7="","",IF(Value!J7=0,"",(Value!J7*100/Feuil1!$C$2-100)/100)) | K7: =IF(Value!K7="","",IF(Value!K7=0,"",(Value!K7*100/Feuil1!$C$2-100)/100)) | L7: =IF(Value!L7="","",IF(Value!L7=0,"",(Value!L7*100/Feuil1!$C$2-100)/100)) | M7: =IF(Value!M7="","",IF(Value!M7=0,"",(Value!M7*100/Feuil1!$C$2-100)/100)) | N7: =IF(Value!N7="","",IF(Value!N7=0,"",(Value!N7*100/Feuil1!$C$2-100)/100)) | O7: =IF(Value!O7="","",IF(Value!O7=0,"",(Value!O7*100/Feuil1!$C$2-100)/100)) | P7: =IF(Value!P7="","",IF(Value!P7=0,"",(Value!P7*100/Feuil1!$C$2-100)/100)) | Q7: =IF(Value!Q7="","",IF(Value!Q7=0,"",(Value!Q7*100/Feuil1!$C$2-100)/100)) | R7: =IF(Value!R7="","",IF(Value!R7=0,"",(Value!R7*100/Feuil1!$C$2-100)/100))
A8: % Résistance Eau | B8: Ré Per Eau | C8: 6 | D8: 1 | E8: =Feuil1!J8 -> 1514 | F8: =E8/C8 -> 252.33333 | G8: =Feuil1!L8 -> 0 | H8: =IF(OR(G8="",G8=0,C8="",C8=0,D8="",D8=0),"",3*G8*C8/D8*Feuil1!$B$2/200+1) | I8: =IF(H8="","",IF(H8=0,"",H8+(SUM($H$2:$H$1004))/2-H8/2)) | J8: =IF(Value!J8="","",IF(Value!J8=0,"",(Value!J8*100/Feuil1!$C$2-100)/100)) | K8: =IF(Value!K8="","",IF(Value!K8=0,"",(Value!K8*100/Feuil1!$C$2-100)/100)) | L8: =IF(Value!L8="","",IF(Value!L8=0,"",(Value!L8*100/Feuil1!$C$2-100)/100)) | M8: =IF(Value!M8="","",IF(Value!M8=0,"",(Value!M8*100/Feuil1!$C$2-100)/100)) | N8: =IF(Value!N8="","",IF(Value!N8=0,"",(Value!N8*100/Feuil1!$C$2-100)/100)) | O8: =IF(Value!O8="","",IF(Value!O8=0,"",(Value!O8*100/Feuil1!$C$2-100)/100)) | P8: =IF(Value!P8="","",IF(Value!P8=0,"",(Value!P8*100/Feuil1!$C$2-100)/100)) | Q8: =IF(Value!Q8="","",IF(Value!Q8=0,"",(Value!Q8*100/Feuil1!$C$2-100)/100)) | R8: =IF(Value!R8="","",IF(Value!R8=0,"",(Value!R8*100/Feuil1!$C$2-100)/100))
A9: % Résistance Feu | B9: Ré Per Feu | C9: 6 | D9: 1 | E9: =Feuil1!J9 -> 1051 | F9: =E9/C9 -> 175.16667 | G9: =Feuil1!L9 -> 0 | H9: =IF(OR(G9="",G9=0,C9="",C9=0,D9="",D9=0),"",3*G9*C9/D9*Feuil1!$B$2/200+1) | I9: =IF(H9="","",IF(H9=0,"",H9+(SUM($H$2:$H$1004))/2-H9/2)) | J9: =IF(Value!J9="","",IF(Value!J9=0,"",(Value!J9*100/Feuil1!$C$2-100)/100)) | K9: =IF(Value!K9="","",IF(Value!K9=0,"",(Value!K9*100/Feuil1!$C$2-100)/100)) | L9: =IF(Value!L9="","",IF(Value!L9=0,"",(Value!L9*100/Feuil1!$C$2-100)/100)) | M9: =IF(Value!M9="","",IF(Value!M9=0,"",(Value!M9*100/Feuil1!$C$2-100)/100)) | N9: =IF(Value!N9="","",IF(Value!N9=0,"",(Value!N9*100/Feuil1!$C$2-100)/100)) | O9: =IF(Value!O9="","",IF(Value!O9=0,"",(Value!O9*100/Feuil1!$C$2-100)/100)) | P9: =IF(Value!P9="","",IF(Value!P9=0,"",(Value!P9*100/Feuil1!$C$2-100)/100)) | Q9: =IF(Value!Q9="","",IF(Value!Q9=0,"",(Value!Q9*100/Feuil1!$C$2-100)/100)) | R9: =IF(Value!R9="","",IF(Value!R9=0,"",(Value!R9*100/Feuil1!$C$2-100)/100))
A10: % Résistance Mêlée | B10: Ré Per Mé | C10: 10 | D10: 1 | E10: =Feuil1!J10 -> 3961 | F10: =E10/C10 -> 396.1 | G10: =Feuil1!L10 -> 0 | H10: =IF(OR(G10="",G10=0,C10="",C10=0,D10="",D10=0),"",3*G10*C10/D10*Feuil1!$B$2/200+1) | I10: =IF(H10="","",IF(H10=0,"",H10+(SUM($H$2:$H$1004))/2-H10/2)) | J10: =IF(Value!J10="","",IF(Value!J10=0,"",(Value!J10*100/Feuil1!$C$2-100)/100)) | K10: =IF(Value!K10="","",IF(Value!K10=0,"",(Value!K10*100/Feuil1!$C$2-100)/100)) | L10: =IF(Value!L10="","",IF(Value!L10=0,"",(Value!L10*100/Feuil1!$C$2-100)/100)) | M10: =IF(Value!M10="","",IF(Value!M10=0,"",(Value!M10*100/Feuil1!$C$2-100)/100)) | N10: =IF(Value!N10="","",IF(Value!N10=0,"",(Value!N10*100/Feuil1!$C$2-100)/100)) | O10: =IF(Value!O10="","",IF(Value!O10=0,"",(Value!O10*100/Feuil1!$C$2-100)/100)) | P10: =IF(Value!P10="","",IF(Value!P10=0,"",(Value!P10*100/Feuil1!$C$2-100)/100)) | Q10: =IF(Value!Q10="","",IF(Value!Q10=0,"",(Value!Q10*100/Feuil1!$C$2-100)/100)) | R10: =IF(Value!R10="","",IF(Value!R10=0,"",(Value!R10*100/Feuil1!$C$2-100)/100))
A11: % Résistance Neutre | B11: Ré Per Neutre | C11: 6 | D11: 1 | E11: =Feuil1!J11 -> 1209 | F11: =E11/C11 -> 201.5 | G11: =Feuil1!L11 -> 0 | H11: =IF(OR(G11="",G11=0,C11="",C11=0,D11="",D11=0),"",3*G11*C11/D11*Feuil1!$B$2/200+1) | I11: =IF(H11="","",IF(H11=0,"",H11+(SUM($H$2:$H$1004))/2-H11/2)) | J11: =IF(Value!J11="","",IF(Value!J11=0,"",(Value!J11*100/Feuil1!$C$2-100)/100)) | K11: =IF(Value!K11="","",IF(Value!K11=0,"",(Value!K11*100/Feuil1!$C$2-100)/100)) | L11: =IF(Value!L11="","",IF(Value!L11=0,"",(Value!L11*100/Feuil1!$C$2-100)/100)) | M11: =IF(Value!M11="","",IF(Value!M11=0,"",(Value!M11*100/Feuil1!$C$2-100)/100)) | N11: =IF(Value!N11="","",IF(Value!N11=0,"",(Value!N11*100/Feuil1!$C$2-100)/100)) | O11: =IF(Value!O11="","",IF(Value!O11=0,"",(Value!O11*100/Feuil1!$C$2-100)/100)) | P11: =IF(Value!P11="","",IF(Value!P11=0,"",(Value!P11*100/Feuil1!$C$2-100)/100)) | Q11: =IF(Value!Q11="","",IF(Value!Q11=0,"",(Value!Q11*100/Feuil1!$C$2-100)/100)) | R11: =IF(Value!R11="","",IF(Value!R11=0,"",(Value!R11*100/Feuil1!$C$2-100)/100))
A12: % Résistance Terre | B12: Ré Per Terre | C12: 6 | D12: 1 | E12: =Feuil1!J12 -> 1438 | F12: =E12/C12 -> 239.66667 | G12: =Feuil1!L12 -> 0 | H12: =IF(OR(G12="",G12=0,C12="",C12=0,D12="",D12=0),"",3*G12*C12/D12*Feuil1!$B$2/200+1) | I12: =IF(H12="","",IF(H12=0,"",H12+(SUM($H$2:$H$1004))/2-H12/2)) | J12: =IF(Value!J12="","",IF(Value!J12=0,"",(Value!J12*100/Feuil1!$C$2-100)/100)) | K12: =IF(Value!K12="","",IF(Value!K12=0,"",(Value!K12*100/Feuil1!$C$2-100)/100)) | L12: =IF(Value!L12="","",IF(Value!L12=0,"",(Value!L12*100/Feuil1!$C$2-100)/100)) | M12: =IF(Value!M12="","",IF(Value!M12=0,"",(Value!M12*100/Feuil1!$C$2-100)/100)) | N12: =IF(Value!N12="","",IF(Value!N12=0,"",(Value!N12*100/Feuil1!$C$2-100)/100)) | O12: =IF(Value!O12="","",IF(Value!O12=0,"",(Value!O12*100/Feuil1!$C$2-100)/100)) | P12: =IF(Value!P12="","",IF(Value!P12=0,"",(Value!P12*100/Feuil1!$C$2-100)/100)) | Q12: =IF(Value!Q12="","",IF(Value!Q12=0,"",(Value!Q12*100/Feuil1!$C$2-100)/100)) | R12: =IF(Value!R12="","",IF(Value!R12=0,"",(Value!R12*100/Feuil1!$C$2-100)/100))
A13: Agilité | B13: Age | C13: 1 | D13: 1 | E13: =Feuil1!J13 -> 99 | F13: =E13/C13 -> 99 | G13: =Feuil1!L13 -> 0 | H13: =IF(OR(G13="",G13=0,C13="",C13=0,D13="",D13=0),"",3*G13*C13/D13*Feuil1!$B$2/200+1) | I13: =IF(H13="","",IF(H13=0,"",H13+(SUM($H$2:$H$1004))/2-H13/2)) | J13: =IF(Value!J13="","",IF(Value!J13=0,"",(Value!J13*100/Feuil1!$C$2-100)/100)) | K13: =IF(Value!K13="","",IF(Value!K13=0,"",(Value!K13*100/Feuil1!$C$2-100)/100)) | L13: =IF(Value!L13="","",IF(Value!L13=0,"",(Value!L13*100/Feuil1!$C$2-100)/100)) | M13: =IF(Value!M13="","",IF(Value!M13=0,"",(Value!M13*100/Feuil1!$C$2-100)/100)) | N13: =IF(Value!N13="","",IF(Value!N13=0,"",(Value!N13*100/Feuil1!$C$2-100)/100)) | O13: =IF(Value!O13="","",IF(Value!O13=0,"",(Value!O13*100/Feuil1!$C$2-100)/100)) | P13: =IF(Value!P13="","",IF(Value!P13=0,"",(Value!P13*100/Feuil1!$C$2-100)/100)) | Q13: =IF(Value!Q13="","",IF(Value!Q13=0,"",(Value!Q13*100/Feuil1!$C$2-100)/100)) | R13: =IF(Value!R13="","",IF(Value!R13=0,"",(Value!R13*100/Feuil1!$C$2-100)/100))
... A51: Vitalité | B51: Vi | C51: 1 | D51: 5 | E51: =Feuil1!J51 -> 183 | F51: =E51/C51 -> 183 | G51: =Feuil1!L51 -> 0 | H51: =IF(OR(G51="",G51=0,C51="",C51=0,D51="",D51=0),"",3*G51*C51/D51*Feuil1!$B$2/200+1) | I51: =IF(H51="","",IF(H51=0,"",H51+(SUM($H$2:$H$1004))/2-H51/2)) | J51: =IF(Value!J51="","",IF(Value!J51=0,"",(Value!J51*100/Feuil1!$C$2-100)/100)) | K51: =IF(Value!K51="","",IF(Value!K51=0,"",(Value!K51*100/Feuil1!$C$2-100)/100)) | L51: =IF(Value!L51="","",IF(Value!L51=0,"",(Value!L51*100/Feuil1!$C$2-100)/100)) | M51: =IF(Value!M51="","",IF(Value!M51=0,"",(Value!M51*100/Feuil1!$C$2-100)/100)) | N51: =IF(Value!N51="","",IF(Value!N51=0,"",(Value!N51*100/Feuil1!$C$2-100)/100)) | O51: =IF(Value!O51="","",IF(Value!O51=0,"",(Value!O51*100/Feuil1!$C$2-100)/100)) | P51: =IF(Value!P51="","",IF(Value!P51=0,"",(Value!P51*100/Feuil1!$C$2-100)/100)) | Q51: =IF(Value!Q51="","",IF(Value!Q51=0,"",(Value!Q51*100/Feuil1!$C$2-100)/100)) | R51: =IF(Value!R51="","",IF(Value!R51=0,"",(Value!R51*100/Feuil1!$C$2-100)/100))

Sheet PrixU
A1: Nom de la stat | B1: Nom de rune | C1: Poids Rune | D1: Stat par rune | E1: Prix Rune | F1: Prix / poids runes
A2: % Dommages distance | B2: Do Per Di | C2: 15 | D2: 1 | E2: 29031 | F2: =E2/C2 -> 1935.4
A3: % Dommages aux sorts | B3: Do Per So | C3: 15 | D3: 1 | E3: 27934 | F3: =E3/C3 -> 1862.2667
A4: % Dommages mêlée | B4: Do Per Mé | C4: 15 | D4: 1 | E4: 9398 | F4: =E4/C4 -> 626.53333
A5: % Dommages d'armes | B5: Do Per Ar | C5: 15 | D5: 1 | E5: 6321 | F5: =E5/C5 -> 421.4
A6: % Résistance Mêlée | B6: Ré Per Mé | C6: 10 | D6: 1 | E6: 3961 | F6: =E6/C6 -> 396.1
A7: Dommage Critique | B7: Do Cri | C7: 5 | D7: 1 | E7: 1562 | F7: =E7/C7 -> 312.4
A8: PA | B8: Ga Pa | C8: 100 | D8: 1 | E8: 27542 | F8: =E8/C8 -> 275.42
A9: PM | B9: Ga Pme | C9: 90 | D9: 1 | E9: 22929 | F9: =E9/C9 -> 254.76667
A10: % Résistance Eau | B10: Ré Per Eau | C10: 6 | D10: 1 | E10: 1514 | F10: =E10/C10 -> 252.33333
A11: Dommage Air | B11: Do Air | C11: 5 | D11: 1 | E11: 1237 | F11: =E11/C11 -> 247.4
A12: Dommage Eau | B12: Do Eau | C12: 5 | D12: 1 | E12: 1208 | F12: =E12/C12 -> 241.6
A13: % Résistance Terre | B13: Ré Per Terre | C13: 6 | D13: 1 | E13: 1438 | F13: =E13/C13 -> 239.66667
... A51: Soin | B51: So | C51: 10 | D51: 1 | E51: 391 | F51: =E51/C51 -> 39.1

Sheet ItemWorth
A1: Baguette de sagesse | B1: 3100 | C1: 5900 | D1: =C1*100/B1-100 -> 90.322581 | E1: 96%->83% | F1: Rune Tac
A2: Baton du Grand Pa Wabbit | B2: 7000 | C2: 12400 | D2: =C2*100/B2-100 -> 77.142857 | E2: 146%->128% | F2: Rune Cri
A3: Baton Tont'ata | B3: 2000 | C3: 3800 | D3: =C3*100/B3-100 -> 90 | E3: 0.93 | F3: Rune Tac
A4: Baguette Ni'Ninnin | B4: 13500 | C4: 19000 | D4: =C4*100/B4-100 -> 40.740741 | E4: 0.75 | F4: Rune Pa
